Workbook

Sheet Exam
B2: Select Your ID from the Dropdown Menu=====> | C2: 5
B3: Last Name: | C3: =VLOOKUP(C2,$XEX$7:$XFA$43,3,FALSE) -> Pudimott | F3: TEST VERSION: | G3: 2026S-Sivin
B4: First Name: | C4: =VLOOKUP(C2,$XEX$7:$XFA$43,4,FALSE) -> Christopher | XEY4: 2026S-Sivin
A5: Please use the Financial Statements provided in the sheet "Financials" for Questions 1 to 20 (Use Methodology As Discussed in Class i.e. GE Model)
A6: 1 | B6: Cost of Good Sold (Excluding D&A) for Next Fiscal Year | C6: =Financials!H9 -> 40313.406
A7: 2 | B7: SG&A Expense for Next Fiscal Year | C7: =Financials!H11 -> 22947.254 | XEX7: 1 | XEZ7: Not Selected | XFA7: Not Selected
A8: 3 | B8: Depreciation & Amortization for Next Fiscal Year | C8: =Financials!H13 -> 2985.5565 | XEX8: 2 | XEY8: A12345678 | XEZ8: Sivin | XFA8: G
A9: 4 | B9: Accounts Receivable for Next Fiscal Year | C9: =Financials!H24 -> 5876.9704 | XEX9: 3 | XEY9: A22402719 | XEZ9: Lin | XFA9: Shu
A10: 5 | B10: Inventories for Next Fiscal Year | C10: =Financials!H25 -> 7359.3874 | XEX10: 4 | XEY10: A22247473 | XEZ10: Ponce | XFA10: Oswaldo
A11: 6 | B11: Accounts Payable for Next Fiscal Year | C11: =Financials!H33 -> 15747.27 | XEX11: 5 | XEY11: A22394373 | XEZ11: Pudimott | XFA11: Christopher
A12: 7 | B12: Capital Expenditures for Next Fiscal Year | C12: =-Financials!H54 -> 3424.6242 | XEX12: 6 | XEY12: A22773518 | XEZ12: Aggarwal | XFA12: Moksha
A13: 8 | B13: Funds from Operations for Next Fiscal Year | C13: =Financials!H52 -> 18744.477 | XEX13: 7 | XEY13: A22773258 | XEZ13: Alberts | XFA13: Anthony
A14: 9 | B14: Cash Dividends for Next Fiscal Year | C14: =-Financials!H56 -> 9504.4146 | XEX14: 8 | XEY14: A23186424 | XEZ14: Braglia | XFA14: Edoardo
A15: 10 | B15: Leverage Ratio for Next Fiscal Year | C15: =(Financials!H32+Financials!H35)/Financials!H39 -> 0.61899416 | XEX15: 9 | XEY15: A19058599 | XEZ15: Butt | XFA15: Smile
A16: 11 | B16: Times Interest Earned for Next Fiscal Year | C16: =Financials!H14/Financials!H15 -> 19.793243 | XEX16: 10 | XEY16: A23147632 | XEZ16: Chamarthi | XFA16: Divya Akshitha
A17: 12 | B17: Current Ratio for Next Fiscal Year | C17: =(Financials!H23+Financials!H24+Financials!H25+Financials!H26)/(Financials!H32+Financials!H33+Financials!H34) -> 0.6805231 | XEX17: 11 | XEY17: A23257742 | XEZ17: Coutant | XFA17: Victor
A18: 13 | B18: ROA for Next Fiscal Year | C18: =Financials!H19/Financials!H30 -> 0.12589971 | XEX18: 12 | XEY18: A23225723 | XEZ18: Farfan Paredes | XFA18: Luis Enrique
A19: 14 | B19: ROE for Next Fiscal Year | C19: =Financials!H19/Financials!H39 -> 0.27505865 | XEX19: 13 | XEY19: A17919006 | XEZ19: Fernandez | XFA19: Raymond
A20: 15 | B20: Quick Ratio for Next Fiscal Year | C20: =(Financials!H23+Financials!H24+Financials!H26)/(Financials!H32+Financials!H33+Financials!H34) -> 0.47932749 | XEX20: 14 | XEY20: A23160957 | XEZ20: Benani | XFA20: Jainam
A21: 16 | B21: ROIC for Next Fiscal Year | C21: =(Financials!H14*(1-Financials!H18/Financials!H17))/(Financials!H32+Financials!H35+Financials!H39) -> 0.17752483 | XEX21: 15 | XEY21: A23258366 | XEZ21: Goel | XFA21: Nandini
A22: 17 | B22: Upside Target Price for Next 12 Months if 30x PE Multiple is assumed | C22: =(Financials!H19/Financials!H42)*30 -> 192.62044 | XEX22: 16 | XEY22: A23147567 | XEZ22: Guglielmi | XFA22: Ludovica
A23: 18 | B23: Downside Target Price for Next 12 Months if 20x PE Multiple is assumed | C23: =(Financials!H19/Financials!H42)*20 -> 128.41363 | XEX23: 17 | XEY23: A23214686 | XEZ23: James | XFA23: Deirdre
A24: 19 | B24: % Upside based on current stock price of $165.55 | C24: =(C22-165.55)/165.55 -> 0.16351824 | XEX24: 18 | XEY24: A18181138 | XEZ24: Jean Baptiste | XFA24: Naedge
A25: 20 | B25: % Downside based on current stock price of $165.55 | C25: =(C23-165.55)/165.55 -> -0.22432117 | XEX25: 19 | XEY25: A18997538 | XEZ25: Juncaj | XFA25: Anton
XEX26: 20 | XEY26: A23196460 | XEZ26: Krohnstad | XFA26: Erik
XEX27: 21 | XEY27: A22850244 | XEZ27: Laverty | XFA27: Kathryn
XEX28: 22 | XEY28: A19199415 | XEZ28: Little | XFA28: Candyce
XEX29: 23 | XEY29: A22773648 | XEZ29: Lombardo | XFA29: Nicholas
XEX30: 24 | XEY30: A23251710 | XEZ30: Magistrelli | XFA30: Federico
XEX31: 25 | XEY31: A22804887 | XEZ31: Mehta | XFA31: Aarnish Rakesh
XEX32: 26 | XEY32: A22833305 | XEZ32: Parekh | XFA32: Mihheir Mehul
XEX33: 27 | XEY33: A22833903 | XEZ33: Parekh | XFA33: Yesha Hitesh
XEX34: 28 | XEY34: A23176635 | XEZ34: Patel | XFA34: Devansh Naresh
XEX35: 29 | XEY35: A17906526 | XEZ35: Perez-Rodriguez | XFA35: Amado
XEX36: 30 | XEY36: A23214829 | XEZ36: Rettinger | XFA36: Matthew
XEX37: 31 | XEY37: A23214725 | XEZ37: Reynaldy | XFA37: Felicia Yvonne
... XEX43: 37 | XEY43: A23286849 | XEZ43: Roth | XFA43: Caroline

Sheet Financials
A1: Procter & Gamble Company
E4: USE 5 year AVERAGE WHERE APPROPRIATE
A7: Income Statement | B7: Jun '20 | C7: Jun '21 | D7: Jun '22 | E7: Jun '23 | F7: Jun '24 | G7: Jun '25 | H7: Next FY
A8: Sales/Revenue | B8: 70950 | C8: 76118 | D8: 80187 | E8: 82006 | F8: 84039 | G8: 84284 | H8: 86653.05
A9: Cost of Good Sold (Excluding D&A) | B9: 31623 | C9: 34239 | D9: 39168 | E9: 39886 | F9: 37704 | G9: 38167 | H9: 40313.406
A10: Gross Income | B10: 39327 | C10: 41879 | D10: 41019 | E10: 42120 | F10: 46335 | G10: 46117 | H10: 46339.644
A11: SG&A Expense | B11: 19922 | C11: 20552 | D11: 20299 | E11: 21049 | F11: 23241 | G11: 22564 | H11: 22947.254
A12: EBITDA | B12: 19405 | C12: 21327 | D12: 20720 | E12: 21071 | F12: 23094 | G12: 23553 | H12: 23392.39
A13: Depreciation & Amortization | B13: 3013 | C13: 2735 | D13: 2807 | E13: 2714 | F13: 2896 | G13: 2847 | H13: 2985.5565
A14: EBIT | B14: 16392 | C14: 18592 | D14: 17913 | E14: 18357 | F14: 20198 | G14: 20706 | H14: 20406.834
A15: Interest Expense | B15: 465 | C15: 502 | D15: 439 | E15: 615 | F15: 1045 | G15: 1031 | H15: 1031
A16: Others & Unusual Expense | B16: 93 | C16: 475 | D16: -521 | E16: -611 | F16: 392 | G16: -492 | H16: -153.9059
A17: Pretax Income | B17: 15834 | C17: 17615 | D17: 17995 | E17: 18353 | F17: 18761 | G17: 20167 | H17: 19529.744
A18: Income Taxes | B18: 2731 | C18: 3263 | D18: 3202 | E18: 3615 | F18: 3787 | G18: 4102 | H18: 3770.8233
A19: Net Income | B19: 13103 | C19: 14352 | D19: 14793 | E19: 14738 | F19: 14974 | G19: 16065 | H19: 15758.921
A22: Balance Sheet
A23: Cash & Equivalents (Cash & ST Investments) | B23: 16181 | C23: 10288 | D23: 7214 | E23: 8246 | F23: 9482 | G23: 9556 | H23: 9556
A24: Accounts Receivable | B24: 4178 | C24: 4725 | D24: 5143 | E24: 5471 | F24: 6118 | G24: 6185 | H24: 5876.9704
A25: Inventories | B25: 5498 | C25: 5983 | D25: 6924 | E25: 7073 | F25: 7016 | G25: 7551 | H25: 7359.3874
A26: Other Current Assets | B26: 2130 | C26: 2095 | D26: 2372 | E26: 1858 | F26: 2093 | G26: 2100 | H26: 2100
A27: Net PP&E | B27: 21542 | C27: 22494 | D27: 21955 | E27: 22690 | F27: 23027 | G27: 24822 | H27: 25261.068
A28: Intangibles | B28: 63693 | C28: 64566 | D28: 63379 | E28: 64442 | F28: 62350 | G28: 63560 | H28: 63560
A29: Other Assets | B29: 7478 | C29: 9156 | D29: 10221 | E29: 11049 | F29: 12284 | G29: 11457 | H29: 11457
A30: Total Assets | B30: 120700 | C30: 119307 | D30: 117208 | E30: 120829 | F30: 122370 | G30: 125231 | H30: 125170.43
A32: Short Term Debt | B32: 11422 | C32: 9108 | D32: 8850 | E32: 10451 | F32: 7434 | G32: 9768 | H32: 9768
A33: Accounts Payable | B33: 12071 | C33: 13720 | D33: 14882 | E33: 14598 | F33: 15364 | G33: 15227 | H33: 15747.27
A34: Other Current Liabilities | B34: 9483 | C34: 10304 | D34: 9349 | E34: 10707 | F34: 10829 | G34: 11063 | H34: 11063
A35: Long Term Debt | B35: 24189 | C35: 23730 | D35: 23443 | E35: 24973 | F35: 25935 | G35: 25696 | H35: 25696
... A42: Common Shares Outstanding | B42: 2625.8 | C42: 2601 | D42: 2539.1 | E42: 2483.9 | F42: 2471.9 | G42: 2454.4 | H42: 2454.4
A44: Check | B44: =B30-B40 -> 0 | C44: =C30-C40 -> 0 | D44: =D30-D40 -> 0 | E44: =E30-E40 -> 0 | F44: =F30-F40 -> 0 | G44: =G30-G40 -> 0 | H44: =H30-H40 -> -6366.7922
A46: Cash Conversion Cycle (Days)
A47: Days of Sales Outstanding | B47: 23.481924 | C47: 21.345772 | D47: 22.458877 | E47: 23.620894 | F47: 25.166798 | G47: 26.639665 | H47: 24.754976
A48: Days of Inventory on Hand | B48: 55.40442 | C48: 56.669078 | D48: 56.117391 | E48: 59.963674 | F48: 63.331096 | G48: 64.818781 | H48: 66.632336
A49: Days of Payables Outstanding | B49: 121.25037 | C49: 125.65409 | D49: 121.63018 | E49: 125.85339 | F49: 134.87049 | G49: 134.36902 | H49: 142.57673
A51: Cash Flow Statement
A52: Funds from Operations | B52: 16116 | C52: 17087 | D52: 17600 | E52: 17452 | F52: 17870 | G52: 18912 | H52: 18744.477
A53: Net Cash Flow - Operating | B53: 17403 | C53: 18371 | D53: 16723 | E53: 16848 | F53: 19845 | G53: 17818 | H53: 18499.498
A54: Capital Expenditures | B54: -3073 | C54: -2787 | D54: -3156 | E54: -3062 | F54: -3322 | G54: -3773 | H54: -3424.6242
A55: Net Cash Flow - Investing | B55: 3045 | C55: -2834 | D55: -4424 | E55: -3500 | F55: -3504 | G55: -3818 | H55: -3424.6242
A56: Cash Dividends | B56: -7789 | C56: -8263 | D56: -8770 | E56: -8999 | F56: -9312 | G56: -9872 | H56: -9504.4146
...
